Workbook
Name _Hlk123206136: 'BL FORM '!#REF!
Name _Hlk123206143: 'BL FORM '!$A$48
Name _Hlk32592103: 'BL FORM '!#REF!

Sheet BL FORM 
A5: SHIPPER
B6: BAYER VIETNAM LTD.
B7: FOR THE ACCOUNT OF BAYER AG
B8: KAISER- WILHELM- ALLEE 1 | L8: B/L No. | M8: HCM-PHLPSE260824
B9: 51373 LEVERKUSEN
B10: GERMANY.
A12: CONSIGNEE
B13: BAYER CROPSCIENCE, INC.
B14: 8TH FLOOR, SCIENCE HUB TOWER 1,
B15: CAMPUS AVENUE CORNER TURIN STREET,
B16: MCKINLEY HILL CYBERPARK,
B17: PINAGSAMA, TAGUIG CITY 1630, PHILIPPINES
B18: TIN NUMBER: 219-883-990-00000.
A19: NOTIFY PARTY
A20: SAME AS CONSIGNEE
A26: PIER | E26: PLACE OF RECEIPT*
E27: HO CHI MINH VIET NAM
A28: VESSEL/VOY | E28: PORT OF LOADING | K28: PORT OF DISCHARGE | O28: PORT OF DELIVERY
A29: SONGA SUCCESS 1054N | E29: TAN CANG CAI MEP | K29: MANILA, PHILIPIINES | O29: =K29 -> MANILA, PHILIPIINES
A30: CARRIER'S RECEIPT | K30: PARTICULARS FUNISHED BY SHIPPER - CARRIER NOT RESPONSIBLE
A31: Container No., Seal No., Mark and Number | F31: No. of container of pkgs | I31: Kind of packages description of goods | P31: Gross weight | Q31: Measurament
I32: SHIPPER'S LOAD A COUNT CONTAINERS
F33: 10 PALLETS | I33: ='[1]HBL SURRENDER '!I32 -> SEALED BY SHIPPER | P33: 4,340.16 KGS | Q33: 10 CBM
A34: ='[1]BL FORM '!A33 -> CY/CY | I34: ='[1]HBL SURRENDER '!I33 -> SAID TO CONTAIN
A35: RFSU3015146/ VNSGN2637961/ 20DC/ 10PP/ 4,430.16 KGS
I36: NOMINEE KL 24X(250ML+250ML) COP PH
I37: 10 PALLETS
A38: TTL: 1X20DC | I38: 09 PALLETS OF 36 BOXES OF 24 BOTTLES OF 500ML
A39: SAY ONE CONTAINER ONLY | I39: 01 PALLETS OF 06 BOXES OF 24 BOTTLES OF 500ML
I40: NET WEIGHT : 7,920.00 PCE
A41: MARKING | I41: UNIT PACK : 0.5 LITRES /PCE
A42: BAYER | I42: GROSS WEIGHT : 4,340.16 KGS
A43: BAYER CROPSCIENCE, INC.
A44: MANILA
A45: 0618190738
A46: NOMINEE KL 24X(250ML+250ML) COP PH
A47: 9080889 10 | I47: HS CODE: 38089319
A56: FREIGHT PREPAID
A58: For delivery of goods apply to | L58: IN WITNESS WHERE OF three (3) Bill of lading all of this tenor and date have been
A59: PACIFIC CHARTER FORWARDERS INC | L59: singed one of which being accomplished of other to stand void
...

Sheet HBL 
A5: SHIPPER
B6: ='BL FORM '!B6 -> BAYER VIETNAM LTD. | L6: BILL OF LADING
B7: ='BL FORM '!B7 -> FOR THE ACCOUNT OF BAYER AG
B8: ='BL FORM '!B8 -> KAISER- WILHELM- ALLEE 1 | K8: B/L No. | L8: B/L No. | M8: ='BL FORM '!M8:P8 -> HCM-PHLPSE260824
B9: ='BL FORM '!B9 -> 51373 LEVERKUSEN
B10: ='BL FORM '!B10 -> GERMANY.
A11: CONSIGNEE
B12: ='BL FORM '!B13 -> BAYER CROPSCIENCE, INC.
B13: ='BL FORM '!B14 -> 8TH FLOOR, SCIENCE HUB TOWER 1,
B14: ='BL FORM '!B15 -> CAMPUS AVENUE CORNER TURIN STREET,
B15: ='BL FORM '!B16 -> MCKINLEY HILL CYBERPARK,
B16: ='BL FORM '!B17 -> PINAGSAMA, TAGUIG CITY 1630, PHILIPPINES
B17: ='BL FORM '!B18 -> TIN NUMBER: 219-883-990-00000.
A18: NOTIFY PARTY
A19: SAME AS CONSIGNEE
A25: PIER | E25: PLACE OF RECEIPT*
E26: ='BL FORM '!E27:I27 -> HO CHI MINH VIET NAM
A27: VESSEL/VOY | E27: PORT OF LOADING | J27: PORT OF DISCHARGE | N27: PORT OF DELIVERY
A28: ='BL FORM '!A29 -> SONGA SUCCESS 1054N | E28: ='BL FORM '!E29:I29 -> TAN CANG CAI MEP | J28: ='BL FORM '!K29 -> MANILA, PHILIPIINES | N28: =J28 -> MANILA, PHILIPIINES
A29: CARRIER'S RECEIPT | J29: PARTICULARS FUNISHED BY SHIPPER - CARRIER NOT RESPONSIBLE
A30: Container No., Seal No., Mark and Number | F30: No. of container of pkgs | I30: Kind of packages description of goods | O30: Gross weight | P30: Measurament
I31: ='BL FORM '!I32 -> SHIPPER'S LOAD A COUNT CONTAINERS
E32: ='BL FORM '!F33 -> 10 PALLETS | I32: ='BL FORM '!I33 -> SEALED BY SHIPPER | O32: ='BL FORM '!P33 -> 4,340.16 KGS | P32: ='BL FORM '!Q33 -> 10 CBM
A33: ='BL FORM '!A34 -> CY/CY | I33: ='BL FORM '!I34 -> SAID TO CONTAIN
A34: ='BL FORM '!A35 -> RFSU3015146/ VNSGN2637961/ 20DC/ 10PP/ 4,430.16 KGS
I35: ='BL FORM '!I36 -> NOMINEE KL 24X(250ML+250ML) COP PH
I36: ='BL FORM '!I37 -> 10 PALLETS
A37: ='BL FORM '!A38 -> TTL: 1X20DC | I37: ='BL FORM '!I38 -> 09 PALLETS OF 36 BOXES OF 24 BOTTLES OF 500ML
A38: ='BL FORM '!A39 -> SAY ONE CONTAINER ONLY | I38: ='BL FORM '!I39 -> 01 PALLETS OF 06 BOXES OF 24 BOTTLES OF 500ML
I39: ='BL FORM '!I40 -> NET WEIGHT : 7,920.00 PCE
A40: ='BL FORM '!A41 -> MARKING | I40: ='BL FORM '!I41 -> UNIT PACK : 0.5 LITRES /PCE
A41: ='BL FORM '!A42 -> BAYER | I41: ='BL FORM '!I42 -> GROSS WEIGHT : 4,340.16 KGS
A42: ='BL FORM '!A43 -> BAYER CROPSCIENCE, INC.
A43: ='BL FORM '!A44 -> MANILA
A44: ='BL FORM '!A45 -> 0618190738
A45: ='BL FORM '!A46 -> NOMINEE KL 24X(250ML+250ML) COP PH
A46: ='BL FORM '!A47 -> 9080889 10
A47: ='BL FORM '!A48 | I47: ='BL FORM '!I47 -> HS CODE: 38089319
A55: ='BL FORM '!A56 -> FREIGHT PREPAID
A62: For delivery of goods apply to | K62: IN WITNESS WHERE OF three (3) Bill of lading all of this tenor and date have been
...

Sheet MBL 
A5: SHIPPER
B6: DAI QUOC VIET SHIPPING CO., LTD
B7: 6TH FLOOR, 607-609 NGUYEN KIEM, DUC
B8: NHUAN WARD, HO CHI MINH CITY, | L8: B/L No. | M8: BSGNC25032547
B9: VIET NAM
B10: EMAIL: DOC9@DAIQUOCVIET.COM
A12: CONSIGNEE
B13: ='BL FORM '!A59 -> PACIFIC CHARTER FORWARDERS INC
B14: ='BL FORM '!A60 -> UNIT 902, PHILFLEX BAY CENTER, CORAL WAY DRIVE
B15: ='BL FORM '!A61 -> CENTRAL BUSINESS PARK 1, PASAY CITY, 1300 METRO
B16: ='BL FORM '!A62 -> MANILA
B17: ='BL FORM '!A63 -> Email: forwarding@pcharter.com / geraldine@pcharter.com
B18: ='BL FORM '!A64 -> Tel: 63-2-2930577, 2930587, 2930588, 2930589
A19: NOTIFY PARTY
A20: SAME AS CONSIGNEE
A26: PIER | E26: PLACE OF RECEIPT*
E27: HO CHI MINH
A28: VESSEL/VOY | E28: PORT OF LOADING | K28: PORT OF DISCHARGE | O28: PORT OF DELIVERY
A29: ='BL FORM '!A29 -> SONGA SUCCESS 1054N | E29: ='BL FORM '!E29:I29 -> TAN CANG CAI MEP | K29: ='[1]BL FORM '!K29 -> NORTH MANILA , PHILIPPINES | O29: =K29 -> NORTH MANILA , PHILIPPINES
A30: CARRIER'S RECEIPT | K30: PARTICULARS FUNISHED BY SHIPPER - CARRIER NOT RESPONSIBLE
A31: Container No., Seal No., Mark and Number | F31: No. of container of pkgs | I31: Kind of packages description of goods | P31: Gross weight | Q31: Measurament
I32: ='BL FORM '!I32 -> SHIPPER'S LOAD A COUNT CONTAINERS
F33: ='BL FORM '!F33 -> 10 PALLETS | I33: ='BL FORM '!I33 -> SEALED BY SHIPPER | P33: ='BL FORM '!P33 -> 4,340.16 KGS | Q33: ='BL FORM '!Q33 -> 10 CBM
A34: ='BL FORM '!A34 -> CY/CY | I34: ='BL FORM '!I34 -> SAID TO CONTAIN
A35: ='BL FORM '!A35 -> RFSU3015146/ VNSGN2637961/ 20DC/ 10PP/ 4,430.16 KGS
I36: ='BL FORM '!I36 -> NOMINEE KL 24X(250ML+250ML) COP PH
I37: ='BL FORM '!I37 -> 10 PALLETS
A38: ='BL FORM '!A38 -> TTL: 1X20DC | I38: ='BL FORM '!I38 -> 09 PALLETS OF 36 BOXES OF 24 BOTTLES OF 500ML
A39: ='BL FORM '!A39 -> SAY ONE CONTAINER ONLY | I39: ='BL FORM '!I39 -> 01 PALLETS OF 06 BOXES OF 24 BOTTLES OF 500ML
I40: ='BL FORM '!I40 -> NET WEIGHT : 7,920.00 PCE
A41: ='BL FORM '!A41 -> MARKING | I41: ='BL FORM '!I41 -> UNIT PACK : 0.5 LITRES /PCE
A42: ='BL FORM '!A42 -> BAYER | I42: ='BL FORM '!I42 -> GROSS WEIGHT : 4,340.16 KGS
A43: ='BL FORM '!A43 -> BAYER CROPSCIENCE, INC.
A44: ='BL FORM '!A44 -> MANILA | I44: ='BL FORM '!I44 -> 0
A45: ='BL FORM '!A45 -> 0618190738 | I45: ='BL FORM '!I45 -> 0
A46: ='BL FORM '!A46 -> NOMINEE KL 24X(250ML+250ML) COP PH | I46: ='BL FORM '!I46 -> 0
A47: ='BL FORM '!A47 -> 9080889 10 | I47: ='BL FORM '!I47 -> HS CODE: 38089319
A48: ='BL FORM '!A48 | I48: ='BL FORM '!I48 -> 0
A49: ='BL FORM '!A49 -> 0 | I49: ='BL FORM '!I49 -> 0
A50: ='BL FORM '!A50 -> 0 | I50: ='BL FORM '!I50 -> 0
...
